Workbook

Sheet DTEN Linkage
A1: No. | B1: date | C1: Request ID | D1: Request | E1: Response
A4: 1 | B4: 46103.061 | C4: ec19e110-c880-4330-ab44-d20bdf567b9f | D4: {LDCMLists={Quantity=0, Register=[]}} | E4: {""LDCMLists"":{""Quantity"":0,""Register"":[]}}
A5: 2 | B5: 46102.409 | C5: a3b86b38-a4de-444c-9269-5fba9b9a3611 | D5: {LDCMLists={Quantity=0, Register=[]}} | E5: {""LDCMLists"":{""Quantity"":0,""Register"":[]}}
A6: 3 | B6: 46102.061 | C6: 2d53b231-e2bb-4ef9-be86-72040b753871 | D6: {LDCMLists={Quantity=164, Register=[{LDCMID=BYC02384, IMEI=860466063177200, ICCID=8966043725100036313, IMSI=520043600654861, ProStatus=PROD, ProDate=20260320173123, SendDate=20260321083211, TypeStatus=OK, NGDate=null, NGRECBY=null, ReplaceSN=null}, {LDCMID=BYC02898, IMEI=860466063181301, ICCID=8966043725100031173, IMSI=520043600654347, ProStatus=PROD, ProDate=20260320173135, SendDate=20260321083211, TypeStatus=OK, NGDate=null, NGRECBY=null, ReplaceSN=null}, {LDCMID=BYC01313, IMEI=860466063180386, ICCID=8966044225100046882, IMSI=520043600661923, ProStatus=PROD, ProDate=20260320173147, SendDate=20260321083211, TypeStatus=OK, NGDate=null, NGRECBY=null, ReplaceSN=null}, {LDCMID=BYC00409, IMEI=860466063155057, ICCID=8966044225100055917, IMSI=520043600662826, ProStatus=PROD, ProDate=20260320173158, SendDate=20260321083211, TypeStatus=OK, NGDate=null, NGRECBY=null, ReplaceSN=null}, {LDCMID=BYC02171, IMEI=860466063106035, ICCID=8966043725100038400, IMSI=520043600655070, ProStatus=PROD, ProDate=20260320173213, SendDate=20260321083211, TypeStatus=OK, NGDate=null, NGRECBY=null, ReplaceSN=null}, {LDCMID=BYC02394, IMEI=860466063106084, ICCID=8966043725100036214, IMSI=520043600654851, ProStatus=PROD, ProDate=20260320173225, SendDate=20260321083211, TypeStatus=OK, NGDate=null, NGRECBY=null, ReplaceSN=null}, {LDCMID=BYC01922, IMEI=860466063090965, ICCID=8966043725100040976, IMSI=520043600655327, ProStatus=PROD, ProDate=20260320173245, SendDate=20260321083211, TypeStatus=OK, NGDate=null, NGRECBY=null, ReplaceSN=null}, {LDCMID=BYC00102, IMEI=860466063106175, ICCID=8966044225100058986, IMSI=520043600663133, ProStatus=PROD, ProDate=20260320173257, SendDate=20260321083211, TypeStatus=OK, NGDate=null, NGRECBY=null, ReplaceSN=null}, {LDCMID=BYC01169, IMEI=860466063090809, ICCID=8966043725100030027, IMSI=520043600654232, ProStatus=PROD, ProDate=20260320173316, SendDate=20260321083211, TypeStatus=OK, NGDate=null, NGRECBY=null, ReplaceSN=null}, {LDCMID=BYC00264, IMEI=860466063193199, ICCID=8966044225100057350, IMSI=520043600662970, ProStatus=PROD, ProDate=20260320173330, SendDate=20260321083211, TypeStatus=OK, NGDate=null, NGRECBY=null, ReplaceSN=null}, {LDCMID=BYC02578, IMEI=860466063145371, ICCID=8966043725100034391, IMSI=520043600654669, ProStatus=PROD, ProDate=20260320173430, SendDate=20260321083211, TypeStatus=OK, NGDate=null, NGRECBY=null, ReplaceSN=null}, {LDCMID=BYC02950, IMEI=860466063173977, ICCID=8966043725100030654, IMSI=520043600654295, ProStatus=PROD, ProDate=20260320173442, SendDate=20260321083211, TypeStatus=OK, NGDate=null, NGRECBY=null, ReplaceSN=null}, {LDCMID=BYC00002, IMEI=860466063148771, ICCID=8966044225100059984, IMSI=520043600663233, ProStatus=PROD, ProDate=20260320173454, SendDate=20260321083211, TypeStatus=OK, NGDate=null, NGRECBY=null, ReplaceSN=null}, {LDCMID=BYC02460, IMEI=860466063148631, ICCID=8966043725100035554, IMSI=520043600654785, ProStatus=PROD, ProDate=20260320173505, SendDate=20260321083211, TypeStatus=OK, NGDate=null, NGRECBY=null, ReplaceSN=null}, {LDCMID=BYC02919, IMEI=860466063175543, ICCID=8966043725100030944, IMSI=520043600654324, ProStatus=PROD, ProDate=20260320173519, SendDate=20260321083211, TypeStatus=OK, NGDate=null, NGRECBY=null, ReplaceSN=null}, {LDCMID=BYC02487, IMEI=860466063148615, ICCID=8966043725100035265, IMSI=520043600654756, ProStatus=PROD, ProDate=20260320173535, SendDate=20260321083211, TypeStatus=OK, NGDate=null, NGRECBY=null, ReplaceSN=null}, {LDCMID=BYC02721, IMEI=860466063145306, ICCID=8966043725100032924, IMSI=520043600654522, ProStatus=PROD, ProDate=20260320173554, SendDate=20260321083211, TypeStatus=OK, NGDate=null, NGRECBY=null, ReplaceSN=null}, {LDCMID=BYC00467, IMEI=860466063145405, ICCID=8966044225100055339, IMSI=520043600662768, ProStatus=PROD, ProDate=20260320173610, SendDate=20260321083211, TypeStatus=OK, NGDate=null, NGRECBY=null, ReplaceSN=null}, {LDCMID=BYC02561, IMEI=860466063172706, ICCID=8966043725100034540, IMSI=520043600654684, ProStatus=PROD, ProDate=20260320173623, SendDate=20260321083211, TypeStatus=OK, NGDate=null, NGRECBY=null, ReplaceSN=null}, {LDCMID=BYC02892, IMEI=860466063172821, ICCID=8966043725100031231, IMSI=520043600654353, ProStatus=PROD, ProDate=20260320173638, SendDate=20260321083211, TypeStatus=OK, NGDate=null, NGRECBY=null, ReplaceSN=null}, {LDCMID=B0203345, IMEI=860466063287074, ICCID=8966044925100032564, IMSI=520043600675491, ProStatus=PROD, ProDate=20260320173851, SendDate=20260321083211, TypeStatus=OK, NGDate=null, NGRECBY=null, ReplaceSN=null}, {LDCMID=B0201140, IMEI=860466063269916, ICCID=8966044925100054618, IMSI=520043600677696, ProStatus=PROD, ProDate=20260320173906, SendDate=20260321083211, TypeStatus=OK, NGDate=null, NGRECBY=null, ReplaceSN=null}, {LDCMID=B0201789, IMEI=860466063288270, ICCID=8966044925100048107, IMSI=520043600677045, ProStatus=PROD, ProDate=20260320173922, SendDate=20260321083211, TypeStatus=OK, NGDate=null, NGRECBY=null, ReplaceSN=null}, {LDCMID=B0201257, IMEI=860466063270021, ICCID=8966044925100053420, IMSI=520043600677577, ProStatus=PROD, ProDate=20260320173935, SendDate=20260321083211, TypeStatus=OK, NGDate=null, NGRECBY=null, ReplaceSN=null}, {LDCMID=B0201882, IMEI=860466063288460, ICCID=8966044925100047190, IMSI=520043600676954, ProStatus=PROD, ProDate=20260320173951, SendDate=20260321083211, TypeStatus=OK, NGDate=null, NGRECBY=null, ReplaceSN=null}, {LDCMID=B0203267, IMEI=860466063288577, ICCID=8966044925100033349, IMSI=520043600675569, ProStatus=PROD, ProDate=20260320174009, SendDate=20260321083211, TypeStatus=OK, NGDate=null, NGRECBY=null, ReplaceSN=null}, {LDCMID=B0201685, IMEI=860466063270047, ICCID=8966044925100049147, IMSI=520043600677149, ProStatus=PROD, ProDate=20260320174023, SendDate=20260321083211, TypeStatus=OK, NGDate=null, NGRECBY=null, ReplaceSN=null}, {LDCMID=B0202117, IMEI=860466063270005, ICCID=8966044925100044841, IMSI=520043600676719, ProStatus=PROD, ProDate=20260320174034, SendDate=20260321083211, TypeStatus=OK, NGDate=null, NGRECBY=null, ReplaceSN=null}, {LDCMID=B0201669, IMEI=860466063288601, ICCID=8966044925100049303, IMSI=520043600677165, ProStatus=PROD, ProDate=20260320174047, SendDate=20260321083211, TypeStatus=OK, NGDate=null, NGRECBY=null, ReplaceSN=null}, {LDCMID=B0201623, IMEI=860466063288585, ICCID=8966044925100049766, IMSI=520043600677211, ProStatus=PROD, ProDate=20260320174101, SendDate=20260321083211, TypeStatus=OK, NGDate=null, NGRECBY=null, ReplaceSN=null}, {LDCMID=B0202905, IMEI=860466063269544, ICCID=8966044925100036946, IMSI=520043600675929, ProStatus=PROD, ProDate=20260320182511, SendDate=20260321083211, TypeStatus=OK, NGDate=null, NGRECBY=null, ReplaceSN=null}, {LDCMID=B0202624, IMEI=860466063287207, ICCID=8966044925100039791, IMSI=520043600676214, ProStatus=PROD, ProDate=20260320182529, SendDate=20260321083211, TypeStatus=OK, NGDate=null, NGRECBY=null, ReplaceSN=null}, {LDCMID=B0202995, IMEI=860466063268827, ICCID=8966044925100036045, IMSI=520043600675839, ProStatus=PROD, ProDate=20260320182544, SendDate=20260321083211, TypeStatus=OK, NGDate=null, NGRECBY=null, ReplaceSN=null}, {LDCMID=B0200626, IMEI=860466063268488, ICCID=8966044925100059740, IMSI=520043600678209, ProStatus=PROD, ProDate=20260320182556, SendDate=20260321083211, TypeStatus=OK, NGDate=null, NGRECBY=null, ReplaceSN=null}, {LDCMID=B0203304, IMEI=860466063268819, ICCID=8966044925100032994, IMSI=520043600675534, ProStatus=PROD, ProDate=20260320182608, SendDate=20260321083211, TypeStatus=OK, NGDate=null, NGRECBY=null, ReplaceSN=null}, {LDCMID=B0200915, IMEI=860466063268777, ICCID=8966044925100056878, IMSI=520043600677922, ProStatus=PROD, ProDate=20260320182622, SendDate=20260321083211, TypeStatus=OK, NGDate=null, NGRECBY=null, ReplaceSN=null}, {LDCMID=B0203349, IMEI=860466063287165, ICCID=8966044925100032523, IMSI=520043600675487, ProStatus=PROD, ProDate=20260320182636, SendDate=20260321083211, TypeStatus=OK, NGDate=null, NGRECBY=null, ReplaceSN=null}, {LDCMID=B0203262, IMEI=860466063287249, ICCID=8966044925100033414, IMSI=520043600675576, ProStatus=PROD, ProDate=20260320182649, SendDate=20260321083211, TypeStatus=OK, NGDate=null, NGRECBY=null, ReplaceSN=null}, {LDCMID=B0203061, IMEI=860466063287173, ICCID=8966044925100035401, IMSI=520043600675775, ProStatus=PROD, ProDate=20260320182704, SendDate=20260321083211, TypeStatus=OK, NGDate=null, NGRECBY=null, ReplaceSN=null}, {LDCMID=B0200724, IMEI=860466063268751, ICCID=8966044925100058767, IMSI=520043600678111, ProStatus=PROD, ProDate=20260320182716, SendDate=20260321083211, TypeStatus=OK, NGDate=null, NGRECBY=null, ReplaceSN=null}, {LDCMID=B0201210, IMEI=860466063287710, ICCID=8966044925100053917, IMSI=520043600677626, ProStatus=PROD, ProDate=20260320182809, SendDate=20260321083211, TypeStatus=OK, NGDate=null, NGRECBY=null, ReplaceSN=null}, {LDCMID=B0201867, IMEI=860466063267977, ICCID=8966044925100047323, IMSI=520043600676967, ProStatus=PROD, ProDate=20260320182822, SendDate=20260321083211, TypeStatus=OK, NGDate=null, NGRECBY=null, ReplaceSN=null}, {LDCMID=B0202119, IMEI=860466063287678, ICCID=8966044925100044825, IMSI=520043600676717, ProStatus=PROD, ProDate=20260320182835, SendDate=20260321083211, TypeStatus=OK, NGDate=null, NGRECBY=null, ReplaceSN=null}, {LDCMID=B0202884, IMEI=860466063287645, ICCID=8966044925100037175, IMSI=520043600675952, ProStatus=PROD, ProDate=20260320182904, SendDate=20260321083211, TypeStatus=OK, NGDate=null, NGRECBY=null, ReplaceSN=null}, {LDCMID=B0201839, IMEI=860466063287603, ICCID=8966044925100047604, IMSI=520043600676995, ProStatus=PROD, ProDate=20260320182917, SendDate=20260321083211, TypeStatus=OK, NGDate=null, NGRECBY=null, ReplaceSN=null}, {LDCMID=B0202090, IMEI=860466063269221, ICCID=8966044925100045137, IMSI=520043600676748, ProStatus=PROD, ProDate=20260320182929, SendDate=20260321083211, TypeStatus=OK, NGDate=null, NGRECBY=null, ReplaceSN=null}, {LDCMID=B0201840, IMEI=860466063269213, ICCID=8966044925100047612, IMSI=520043600676996, ProStatus=PROD, ProDate=20260320182945, SendDate=20260321083211, TypeStatus=OK, NGDate=null, NGRECBY=null, ReplaceSN=null}, {LDCMID=B0203287, IMEI=860466063287629, ICCID=8966044925100033141, IMSI=520043600675549, ProStatus=PROD, ProDate=20260320182957, SendDate=20260321083211, TypeStatus=OK, NGDate=null, NGRECBY=null, ReplaceSN=null}, {LDCMID=B0201160, IMEI=860466063287702, ICCID=8966044925100054410, IMSI=520043600677676, ProStatus=PROD, ProDate=20260320183011, SendDate=20260321083211, TypeStatus=OK, NGDate=null, NGRECBY=null, ReplaceSN=null}, {LDCMID=B0202825, IMEI=860466063287652, ICCID=8966044925100037746, IMSI=520043600676009, ProStatus=PROD, ProDate=20260320183024, SendDate=20260321083211, TypeStatus=OK, NGDate=null, NGRECBY=null, ReplaceSN=null}, {LDCMID=B0202842, IMEI=860466063269262, ICCID=8966044925100037597, IMSI=520043600675994, ProStatus=PROD, ProDate=20260320183114, SendDate=20260321083211, TypeStatus=OK, NGDate=null, NGRECBY=null, ReplaceSN=null}, {LDCMID=B0202097, IMEI=860466063287694, ICCID=8966044925100045046, IMSI=520043600676739, ProStatus=PROD, ProDate=20260320183131, SendDate=20260321083211, TypeStatus=OK, NGDate=null, NGRECBY=null, ReplaceSN=null}, {LDCMID=B0202636, IMEI=860466063269197, ICCID=8966044925100039676, IMSI=520043600676202, ProStatus=PROD, ProDate=20260320183143, SendDate=20260321083211, TypeStatus=OK, NGDate=null, NGRECBY=null, ReplaceSN=null}, {LDCMID=B0201341, IMEI=860466063287660, ICCID=8966044925100052588, IMSI=520043600677493, ProStatus=PROD, ProDate=20260320183154, SendDate=20260321083211, TypeStatus=OK, NGDate=null, NGRECBY=null, ReplaceSN=null}, {LDCMID=B0202139, IMEI=860466063269239, ICCID=8966044925100044643, IMSI=520043600676699, ProStatus=PROD, ProDate=20260320183206, SendDate=20260321083211, TypeStatus=OK, NGDate=null, NGRECBY=null, ReplaceSN=null}, {LDCMID=B0202982, IMEI=860466063287371, ICCID=8966044925100036193, IMSI=520043600675854, ProStatus=PROD, ProDate=20260320183221, SendDate=20260321083211, TypeStatus=OK, NGDate=null, NGRECBY=null, ReplaceSN=null}, {LDCMID=B0201956, IMEI=860466063269270, ICCID=8966044925100046457, IMSI=520043600676880, ProStatus=PROD, ProDate=20260320183239, SendDate=20260321083211, TypeStatus=OK, NGDate=null, NGRECBY=null, ReplaceSN=null}, {LDCMID=B0202869, IMEI=860466063287454, ICCID=8966044925100037308, IMSI=520043600675965, ProStatus=PROD, ProDate=20260320183251, SendDate=20260321083211, TypeStatus=OK, NGDate=null, NGRECBY=null, ReplaceSN=null}, {LDCMID=B0203177, IMEI=860466063287595, ICCID=8966044925100034248, IMSI=520043600675659, ProStatus=PROD, ProDate=20260320183304, SendDate=20260321083211, TypeStatus=OK, NGDate=null, NGRECBY=null, ReplaceSN=null}, {LDCMID=B0200383, IMEI=860466063270450, ICCID=8966044925100073832, IMSI=520043600679618, ProStatus=PROD, ProDate=20260320183318, SendDate=20260321083211, TypeStatus=OK, NGDate=null, NGRECBY=null, ReplaceSN=null}, {LDCMID=B0202895, IMEI=860466063286993, ICCID=8966044925100037043, IMSI=520043600675939, ProStatus=PROD, ProDate=20260320183417, SendDate=20260321083211, TypeStatus=OK, NGDate=null, NGRECBY=null, ReplaceSN=null}, {LDCMID=B0202717, IMEI=860466063287033, ICCID=8966044925100038843, IMSI=520043600676119, ProStatus=PROD, ProDate=20260320183428, SendDate=20260321083211, TypeStatus=OK, NGDate=null, NGRECBY=null, ReplaceSN=null}, {LDCMID=B0202389, IMEI=860466063268686, ICCID=8966044925100042100, IMSI=520043600676445, ProStatus=PROD, ProDate=20260320183441, SendDate=20260321083211, TypeStatus=OK, NGDate=null, NGRECBY=null, ReplaceSN=null}, {LDCMID=B0203101, IMEI=860466063287116, ICCID=8966044925100035005, IMSI=520043600675735, ProStatus=PROD, ProDate=20260320183456, SendDate=20260321083211, TypeStatus=OK, NGDate=null, NGRECBY=null, ReplaceSN=null}, {LDCMID=B0202089, IMEI=860466063269254, ICCID=8966044925100045129, IMSI=520043600676747, ProStatus=PROD, ProDate=20260320183508, SendDate=20260321083211, TypeStatus=OK, NGDate=null, NGRECBY=null, ReplaceSN=null}, {LDCMID=B0201419, IMEI=860466063268652, ICCID=8966044925100051804, IMSI=520043600677415, ProStatus=PROD, ProDate=20260320183521, SendDate=20260321083211, TypeStatus=OK, NGDate=null, NGRECBY=null, ReplaceSN=null}, {LDCMID=B0202506, IMEI=860466063287017, ICCID=8966044925100040955, IMSI=520043600676330, ProStatus=PROD, ProDate=20260320183533, SendDate=20260321083211, TypeStatus=OK, NGDate=null, NGRECBY=null, ReplaceSN=null}, {LDCMID=B0202975, IMEI=860466063268629, ICCID=8966044925100036243, IMSI=520043600675859, ProStatus=PROD, ProDate=20260320183558, SendDate=20260321083211, TypeStatus=OK, NGDate=null, NGRECBY=null, ReplaceSN=null}, {LDCMID=B0203310, IMEI=860466063268694, ICCID=8966044925100032937, IMSI=520043600675528, ProStatus=PROD, ProDate=20260320183611, SendDate=20260321083211, TypeStatus=OK, NGDate=null, NGRECBY=null, ReplaceSN=null}, {LDCMID=B0201552, IMEI=860466063268223, ICCID=8966044925100050491, IMSI=520043600677284, ProStatus=PROD, ProDate=20260320183630, SendDate=20260321083211, TypeStatus=OK, NGDate=null, NGRECBY=null, ReplaceSN=null}, {LDCMID=B0200731, IMEI=860466063268926, ICCID=8966044925100058676, IMSI=520043600678102, ProStatus=PROD, ProDate=20260320183954, SendDate=20260321083211, TypeStatus=OK, NGDate=null, NGRECBY=null, ReplaceSN=null}, {LDCMID=B0201093, IMEI=860466063287223, ICCID=8966044925100055060, IMSI=520043600677741, ProStatus=PROD, ProDate=20260320184006, SendDate=20260321083211, TypeStatus=OK, NGDate=null, NGRECBY=null, ReplaceSN=null}, {LDCMID=B0201902, IMEI=860466063287439, ICCID=8966044925100046994, IMSI=520043600676934, ProStatus=PROD, ProDate=20260320184018, SendDate=20260321083211, TypeStatus=OK, NGDate=null, NGRECBY=null, ReplaceSN=null}, {LDCMID=B0203163, IMEI=860466063268835, ICCID=8966044925100034388, IMSI=520043600675673, ProStatus=PROD, ProDate=20260320184029, SendDate=20260321083211, TypeStatus=OK, NGDate=null, NGRECBY=null, ReplaceSN=null}, {LDCMID=B0201376, IMEI=860466063286829, ICCID=8966044925100052257, IMSI=520043600677460, ProStatus=PROD, ProDate=20260320184041, SendDate=20260321083211, TypeStatus=OK, NGDate=null, NGRECBY=null, ReplaceSN=null}, {LDCMID=B0202858, IMEI=860466063268066, ICCID=8966044925100037431, IMSI=520043600675978, ProStatus=PROD, ProDate=20260320184057, SendDate=20260321083211, TypeStatus=OK, NGDate=null, NGRECBY=null, ReplaceSN=null}, {LDCMID=B0201150, IMEI=860466063268157, ICCID=8966044925100054519, IMSI=520043600677686, ProStatus=PROD, ProDate=20260320184114, SendDate=20260321083211, TypeStatus=OK, NGDate=null, NGRECBY=null, ReplaceSN=null}, {LDCMID=B0200954, IMEI=860466063268199, ICCID=8966044925100056530, IMSI=520043600677888, ProStatus=PROD, ProDate=20260320184127, SendDate=20260321083211, TypeStatus=OK, NGDate=null, NGRECBY=null, ReplaceSN=null}, {LDCMID=B0202749, IMEI=860466063286563, ICCID=8966044925100038520, IMSI=520043600676087, ProStatus=PROD, ProDate=20260320184142, SendDate=20260321083211, TypeStatus=OK, NGDate=null, NGRECBY=null, ReplaceSN=null}, {LDCMID=B0202663, IMEI=860466063286555, ICCID=8966044925100039387, IMSI=520043600676173, ProStatus=PROD, ProDate=20260320184158, SendDate=20260321083211, TypeStatus=OK, NGDate=null, NGRECBY=null, ReplaceSN=null}, {LDCMID=B0201624, IMEI=860466063286621, ICCID=8966044925100049774, IMSI=520043600677212, ProStatus=PROD, ProDate=20260320184250, SendDate=20260321083211, TypeStatus=OK, NGDate=null, NGRECBY=null, ReplaceSN=null}, {LDCMID=B0201903, IMEI=860466063268041, ICCID=8966044925100046960, IMSI=520043600676931, ProStatus=PROD, ProDate=20260320184302, SendDate=20260321083211, TypeStatus=OK, NGDate=null, NGRECBY=null, ReplaceSN=null}, {LDCMID=B0201888, IMEI=860466063268108, ICCID=8966044925100047133, IMSI=520043600676948, ProStatus=PROD, ProDate=20260320184314, SendDate=20260321083211, TypeStatus=OK, NGDate=null, NGRECBY=null, ReplaceSN=null}, {LDCMID=B0201723, IMEI=860466063286548, ICCID=8966044925100048768, IMSI=520043600677111, ProStatus=PROD, ProDate=20260320184329, SendDate=20260321083211, TypeStatus=OK, NGDate=null, NGRECBY=null, ReplaceSN=null}, {LDCMID=B0203172, IMEI=860466063286571, ICCID=8966044925100034313, IMSI=520043600675666, ProStatus=PROD, ProDate=20260320184341, SendDate=20260321083211, TypeStatus=OK, NGDate=null, NGRECBY=null, ReplaceSN=null}, {LDCMID=B0200388, IMEI=860466063288908, ICCID=8966044925100073808, IMSI=520043600679615, ProStatus=PROD, ProDate=20260320184358, SendDate=20260321083211, TypeStatus=OK, NGDate=null, NGRECBY=null, ReplaceSN=null}, {LDCMID=B0200281, IMEI=860466063270526, ICCID=8966044925100074855, IMSI=520043600679720, ProStatus=PROD, ProDate=20260320184411, SendDate=20260321083211, TypeStatus=OK, NGDate=null, NGRECBY=null, ReplaceSN=null}, {LDCMID=B0200369, IMEI=860466063270500, ICCID=8966044925100073972, IMSI=520043600679632, ProStatus=PROD, ProDate=20260320184425, SendDate=20260321083211, TypeStatus=OK, NGDate=null, NGRECBY=null, ReplaceSN=null}, {LDCMID=B0201665, IMEI=860466063270229, ICCID=8966044925100049345, IMSI=520043600677169, ProStatus=PROD, ProDate=20260320184442, SendDate=20260321083211, TypeStatus=OK, NGDate=null, NGRECBY=null, ReplaceSN=null}, {LDCMID=B0202883, IMEI=860466063288940, ICCID=8966044925100037167, IMSI=520043600675951, ProStatus=PROD, ProDate=20260320184456, SendDate=20260321083211, TypeStatus=OK, NGDate=null, NGRECBY=null, ReplaceSN=null}, {LDCMID=B0201138, IMEI=860466063268090, ICCID=8966044925100054634, IMSI=520043600677698, ProStatus=PROD, ProDate=20260320184607, SendDate=20260321083211, TypeStatus=OK, NGDate=null, NGRECBY=null, ReplaceSN=null}, {LDCMID=B0203022, IMEI=860466063286589, ICCID=8966044925100035799, IMSI=520043600675814, ProStatus=PROD, ProDate=20260320184619, SendDate=20260321083211, TypeStatus=OK, NGDate=null, NGRECBY=null, ReplaceSN=null}, {LDCMID=B0201361, IMEI=860466063268215, ICCID=8966044925100052380, IMSI=520043600677473, ProStatus=PROD, ProDate=20260320184630, SendDate=20260321083211, TypeStatus=OK, NGDate=null, NGRECBY=null, ReplaceSN=null}, {LDCMID=B0203247, IMEI=860466063286530, ICCID=8966044925100033547, IMSI=520043600675589, ProStatus=PROD, ProDate=20260320184645, SendDate=20260321083211, TypeStatus=OK, NGDate=null, NGRECBY=null, ReplaceSN=null}, {LDCMID=B0203019, IMEI=860466063286498, ICCID=8966044925100035807, IMSI=520043600675815, ProStatus=PROD, ProDate=20260320184701, SendDate=20260321083211, TypeStatus=OK, NGDate=null, NGRECBY=null, ReplaceSN=null}, {LDCMID=B0200065, IMEI=860466063286407, ICCID=8966044925100077650, IMSI=520043600680000, ProStatus=PROD, ProDate=20260320184713, SendDate=20260321083211, TypeStatus=OK, NGDate=null, NGRECBY=null, ReplaceSN=null}, {LDCMID=B0202942, IMEI=860466063286613, ICCID=8966044925100036599, IMSI=520043600675894, ProStatus=PROD, ProDate=20260320184730, SendDate=20260321083211, TypeStatus=OK, NGDate=null, NGRECBY=null, ReplaceSN=null}, {LDCMID=B0202738, IMEI=860466063286522, ICCID=8966044925100038652, IMSI=520043600676100, ProStatus=PROD, ProDate=20260320184742, SendDate=20260321083211, TypeStatus=OK, NGDate=null, NGRECBY=null, ReplaceSN=null}, {LDCMID=B0101680, IMEI=860466063268140, ICCID=8966044225100073233, IMSI=520043600664558, ProStatus=PROD, ProDate=20260320184756, SendDate=20260321083211, TypeStatus=OK, NGDate=null, NGRECBY=null, ReplaceSN=null}, {LDCMID=B0203238, IMEI=860466063286605, ICCID=8966044925100033653, IMSI=520043600675600, ProStatus=PROD, ProDate=20260320184813, SendDate=20260321083211, TypeStatus=OK, NGDate=null, NGRECBY=null, ReplaceSN=null}, {LDCMID=B0202176, IMEI=860466063287959, ICCID=8966044925100044296, IMSI=520043600676664, ProStatus=PROD, ProDate=20260320184903, SendDate=20260321083211, TypeStatus=OK, NGDate=null, NGRECBY=null, ReplaceSN=null}, {LDCMID=B0202903, IMEI=860466063287736, ICCID=8966044925100036961, IMSI=520043600675931, ProStatus=PROD, ProDate=20260320184916, SendDate=20260321083211, TypeStatus=OK, NGDate=null, NGRECBY=null, ReplaceSN=null}, {LDCMID=B0202099, IMEI=860466063287744, ICCID=8966044925100045020, IMSI=520043600676737, ProStatus=PROD, ProDate=20260320184927, SendDate=20260321083211, TypeStatus=OK, NGDate=null, NGRECBY=null, ReplaceSN=null}, {LDCMID=B0201554, IMEI=860466063269551, ICCID=8966044925100050475, IMSI=520043600677282, ProStatus=PROD, ProDate=20260320184940, SendDate=20260321083211, TypeStatus=OK, NGDate=null, NGRECBY=null, ReplaceSN=null}, {LDCMID=B0200396, IMEI=860466063287975, ICCID=8966044925100073725, IMSI=520043600679607, ProStatus=PROD, ProDate=20260320184956, SendDate=20260321083211, TypeStatus=OK, NGDate=null, NGRECBY=null, ReplaceSN=null}, {LDCMID=B0201493, IMEI=860466063268983, ICCID=8966044925100051069, IMSI=520043600677341, ProStatus=PROD, ProDate=20260320185008, SendDate=20260321083211, TypeStatus=OK, NGDate=null, NGRECBY=null, ReplaceSN=null}, {LDCMID=B0202912, IMEI=860466063269486, ICCID=8966044925100036896, IMSI=520043600675924, ProStatus=PROD, ProDate=20260320185025, SendDate=20260321083211, TypeStatus=OK, NGDate=null, NGRECBY=null, ReplaceSN=null}, {LDCMID=B0203040, IMEI=860466063269478, ICCID=8966044925100030030, IMSI=520043600675238, ProStatus=PROD, ProDate=20260320185038, SendDate=20260321083211, TypeStatus=OK, NGDate=null, NGRECBY=null, ReplaceSN=null}, {LDCMID=B0201223, IMEI=860466063287991, ICCID=8966044925100053768, IMSI=520043600677611, ProStatus=PROD, ProDate=20260320185051, SendDate=20260321083211, TypeStatus=OK, NGDate=null, NGRECBY=null, ReplaceSN=null}, {LDCMID=B0202850, IMEI=860466063287082, ICCID=8966044925100037514, IMSI=520043600675986, ProStatus=PROD, ProDate=20260320185106, SendDate=20260321083211, TypeStatus=OK, NGDate=null, NGRECBY=null, ReplaceSN=null}, {LDCMID=B0202988, IMEI=860466063269007, ICCID=8966044925100036136, IMSI=520043600675848, ProStatus=PROD, ProDate=20260320185503, SendDate=20260321083211, TypeStatus=OK, NGDate=null, NGRECBY=null, ReplaceSN=null}, {LDCMID=B0201250, IMEI=860466063287298, ICCID=8966044925100053511, IMSI=520043600677586, ProStatus=PROD, ProDate=20260320185517, SendDate=20260321083211, TypeStatus=OK, NGDate=null, NGRECBY=null, ReplaceSN=null}, {LDCMID=B0202951, IMEI=860466063268843, ICCID=8966044925100036482, IMSI=520043600675883, ProStatus=PROD, ProDate=20260320185529, SendDate=20260321083211, TypeStatus=OK, NGDate=null, NGRECBY=null, ReplaceSN=null}, {LDCMID=B0202513, IMEI=860466063287272, ICCID=8966044925100040864, IMSI=520043600676321, ProStatus=PROD, ProDate=20260320185544, SendDate=20260321083211, TypeStatus=OK, NGDate=null, NGRECBY=null, ReplaceSN=null}, {LDCMID=B0203296, IMEI=860466063287447, ICCID=8966044925100033075, IMSI=520043600675542, ProStatus=PROD, ProDate=20260320185557, SendDate=20260321083211, TypeStatus=OK, NGDate=null, NGRECBY=null, ReplaceSN=null}, {LDCMID=B0201149, IMEI=860466063287538, ICCID=8966044925100054501, IMSI=520043600677685, ProStatus=PROD, ProDate=20260320185614, SendDate=20260321083211, TypeStatus=OK, NGDate=null, NGRECBY=null, ReplaceSN=null}, {LDCMID=B0202220, IMEI=860466063287561, ICCID=8966044925100043819, IMSI=520043600676616, ProStatus=PROD, ProDate=20260320185628, SendDate=20260321083211, TypeStatus=OK, NGDate=null, NGRECBY=null, ReplaceSN=null}, {LDCMID=B0202836, IMEI=860466063287520, ICCID=8966044925100037654, IMSI=520043600676000, ProStatus=PROD, ProDate=20260320185641, SendDate=20260321083211, TypeStatus=OK, NGDate=null, NGRECBY=null, ReplaceSN=null}, {LDCMID=B0202664, IMEI=860466063287579, ICCID=8966044925100039395, IMSI=520043600676174, ProStatus=PROD, ProDate=20260320185700, SendDate=20260321083211, TypeStatus=OK, NGDate=null, NGRECBY=null, ReplaceSN=null}, {LDCMID=B0202250, IMEI=860466063287546, ICCID=8966044925100043512, IMSI=520043600676586, ProStatus=PROD, ProDate=20260320185714, SendDate=20260321083211, TypeStatus=OK, NGDate=null, NGRECBY=null, ReplaceSN=null}, {LDCMID=B0202213, IMEI=860466063269106, ICCID=8966044925100043868, IMSI=520043600676621, ProStatus=PROD, ProDate=20260320185815, SendDate=20260321083211, TypeStatus=OK, NGDate=null, NGRECBY=null, ReplaceSN=null}, {LDCMID=B0201537, IMEI=860466063269098, ICCID=8966044925100050624, IMSI=520043600677297, ProStatus=PROD, ProDate=20260320185827, SendDate=20260321083211, TypeStatus=OK, NGDate=null, NGRECBY=null, ReplaceSN=null}, {LDCMID=B0203213, IMEI=860466063287512, ICCID=8966044925100033885, IMSI=520043600675623, ProStatus=PROD, ProDate=20260320185838, SendDate=20260321083211, TypeStatus=OK, NGDate=null, NGRECBY=null, ReplaceSN=null}, {LDCMID=B0201684, IMEI=860466063268942, ICCID=8966044925100049170, IMSI=520043600677152, ProStatus=PROD, ProDate=20260320185851, SendDate=20260321083211, TypeStatus=OK, NGDate=null, NGRECBY=null, ReplaceSN=null}, {LDCMID=B0201500, IMEI=860466063287637, ICCID=8966044925100051010, IMSI=520043600677336, ProStatus=PROD, ProDate=20260320185903, SendDate=20260321083211, TypeStatus=OK, NGDate=null, NGRECBY=null, ReplaceSN=null}, {LDCMID=B0203590, IMEI=860466063269171, ICCID=8966044925100030139, IMSI=520043600675248, ProStatus=PROD, ProDate=20260320185919, SendDate=20260321083211, TypeStatus=OK, NGDate=null, NGRECBY=null, ReplaceSN=null}, {LDCMID=B0203206, IMEI=860466063269163, ICCID=8966044925100033976, IMSI=520043600675632, ProStatus=PROD, ProDate=20260320185932, SendDate=20260321083211, TypeStatus=OK, NGDate=null, NGRECBY=null, ReplaceSN=null}, {LDCMID=B0202892, IMEI=860466063269080, ICCID=8966044925100037092, IMSI=520043600675944, ProStatus=PROD, ProDate=20260320185946, SendDate=20260321083211, TypeStatus=OK, NGDate=null, NGRECBY=null, ReplaceSN=null}, {LDCMID=B0203176, IMEI=860466063269064, ICCID=8966044925100034271, IMSI=520043600675662, ProStatus=PROD, ProDate=20260320185958, SendDate=20260321083211, TypeStatus=OK, NGDate=null, NGRECBY=null, ReplaceSN=null}, {LDCMID=B0202823, IMEI=860466063287611, ICCID=8966044925100037761, IMSI=520043600676011, ProStatus=PROD, ProDate=20260320190012, SendDate=20260321083211, TypeStatus=OK, NGDate=null, NGRECBY=null, ReplaceSN=null}, {LDCMID=B0200538, IMEI=860466063270161, ICCID=8966044925100072305, IMSI=520043600679465, ProStatus=PROD, ProDate=20260320190116, SendDate=20260321083211, TypeStatus=OK, NGDate=null, NGRECBY=null, ReplaceSN=null}, {LDCMID=B0202517, IMEI=860466063288866, ICCID=8966044925100040823, IMSI=520043600676317, ProStatus=PROD, ProDate=20260320190130, SendDate=20260321083211, TypeStatus=OK, NGDate=null, NGRECBY=null, ReplaceSN=null}, {LDCMID=B0201229, IMEI=860466063288817, ICCID=8966044925100053701, IMSI=520043600677605, ProStatus=PROD, ProDate=20260320190146, SendDate=20260321083211, TypeStatus=OK, NGDate=null, NGRECBY=null, ReplaceSN=null}, {LDCMID=B0203284, IMEI=860466063270492, ICCID=8966044925100033190, IMSI=520043600675554, ProStatus=PROD, ProDate=20260320190158, SendDate=20260321083211, TypeStatus=OK, NGDate=null, NGRECBY=null, ReplaceSN=null}, {LDCMID=B0200600, IMEI=860466063270443, ICCID=8966044925100059989, IMSI=520043600678233, ProStatus=PROD, ProDate=20260320190212, SendDate=20260321083211, TypeStatus=OK, NGDate=null, NGRECBY=null, ReplaceSN=null}, {LDCMID=B0203169, IMEI=860466063270385, ICCID=8966044925100034321, IMSI=520043600675667, ProStatus=PROD, ProDate=20260320190225, SendDate=20260321083211, TypeStatus=OK, NGDate=null, NGRECBY=null, ReplaceSN=null}, {LDCMID=B0201490, IMEI=860466063270187, ICCID=8966044925100051119, IMSI=520043600677346, ProStatus=PROD, ProDate=20260320190239, SendDate=20260321083211, TypeStatus=OK, NGDate=null, NGRECBY=null, ReplaceSN=null}, {LDCMID=B0201122, IMEI=860466063288882, ICCID=8966044925100054790, IMSI=520043600677714, ProStatus=PROD, ProDate=20260320190252, SendDate=20260321083211, TypeStatus=OK, NGDate=null, NGRECBY=null, ReplaceSN=null}, {LDCMID=B0203338, IMEI=860466063270468, ICCID=8966044925100032655, IMSI=520043600675500, ProStatus=PROD, ProDate=20260320190306, SendDate=20260321083211, TypeStatus=OK, NGDate=null, NGRECBY=null, ReplaceSN=null}, {LDCMID=B0203382, IMEI=860466063270476, ICCID=8966044925100032218, IMSI=520043600675456, ProStatus=PROD, ProDate=20260320190321, SendDate=20260321083211, TypeStatus=OK, NGDate=null, NGRECBY=null, ReplaceSN=null}, {LDCMID=B0202747, IMEI=860466063267878, ICCID=8966044925100038546, IMSI=520043600676089, ProStatus=PROD, ProDate=20260320190452, SendDate=20260321083211, TypeStatus=OK, NGDate=null, NGRECBY=null, ReplaceSN=null}, {LDCMID=B0202750, IMEI=860466063286167, ICCID=8966044925100038538, IMSI=520043600676088, ProStatus=PROD, ProDate=20260320190504, SendDate=20260321083211, TypeStatus=OK, NGDate=null, NGRECBY=null, ReplaceSN=null}, {LDCMID=B0202466, IMEI=860466063267753, ICCID=8966044925100041359, IMSI=520043600676370, ProStatus=PROD, ProDate=20260320190521, SendDate=20260321083211, TypeStatus=OK, NGDate=null, NGRECBY=null, ReplaceSN=null}, {LDCMID=B0201215, IMEI=860466063286282, ICCID=8966044925100053842, IMSI=520043600677619, ProStatus=PROD, ProDate=20260320190533, SendDate=20260321083211, TypeStatus=OK, NGDate=null, NGRECBY=null, ReplaceSN=null}, {LDCMID=B0202182, IMEI=860466063286159, ICCID=8966044925100044197, IMSI=520043600676654, ProStatus=PROD, ProDate=20260320190546, SendDate=20260321083211, TypeStatus=OK, NGDate=null, NGRECBY=null, ReplaceSN=null}, {LDCMID=B0202333, IMEI=860466063287587, ICCID=8966044925100042662, IMSI=520043600676501, ProStatus=PROD, ProDate=20260320190601, SendDate=20260321083211, TypeStatus=OK, NGDate=null, NGRECBY=null, ReplaceSN=null}, {LDCMID=B0203302, IMEI=860466063268959, ICCID=8966044925100033018, IMSI=520043600675536, ProStatus=PROD, ProDate=20260320190615, SendDate=20260321083211, TypeStatus=OK, NGDate=null, NGRECBY=null, ReplaceSN=null}, {LDCMID=B0202223, IMEI=860466063269122, ICCID=8966044925100043769, IMSI=520043600676611, ProStatus=PROD, ProDate=20260320190628, SendDate=20260321083211, TypeStatus=OK, NGDate=null, NGRECBY=null, ReplaceSN=null}, {LDCMID=B0203168, IMEI=860466063269189, ICCID=8966044925100034354, IMSI=520043600675670, ProStatus=PROD, ProDate=20260320190643, SendDate=20260321083211, TypeStatus=OK, NGDate=null, NGRECBY=null, ReplaceSN=null}, {LDCMID=B0203531, IMEI=860466063269130, ICCID=8966044925100030204, IMSI=520043600675255, ProStatus=PROD, ProDate=20260320190658, SendDate=20260321083211, TypeStatus=OK, NGDate=null, NGRECBY=null, ReplaceSN=null}, {LDCMID=B0202687, IMEI=860466063268991, ICCID=8966044925100039148, IMSI=520043600676149, ProStatus=PROD, ProDate=20260320190753, SendDate=20260321083211, TypeStatus=OK, NGDate=null, NGRECBY=null, ReplaceSN=null}, {LDCMID=B0202064, IMEI=860466063268967, ICCID=8966044925100045392, IMSI=520043600676774, ProStatus=PROD, ProDate=20260320190805, SendDate=20260321083211, TypeStatus=OK, NGDate=null, NGRECBY=null, ReplaceSN=null}, {LDCMID=B0200033, IMEI=860466063287389, ICCID=8966044925100077304, IMSI=520043600679965, ProStatus=PROD, ProDate=20260320190817, SendDate=20260321083211, TypeStatus=OK, NGDate=null, NGRECBY=null, ReplaceSN=null}, {LDCMID=B0202673, IMEI=860466063287181, ICCID=8966044925100039288, IMSI=520043600676163, ProStatus=PROD, ProDate=20260320190830, SendD | E6: {""LDCMLists"":{""Quantity"":164,""Register"":[{""LDCMID"":""BYC02384"",""StatusReg"":""Process completed successfully"",""ResDate"":""2026-03-21 01:28:29""},{""LDCMID"":""BYC02898"",""StatusReg"":""Process completed successfully"",""ResDate"":""2026-03-21 01:28:29""},{""LDCMID"":""BYC01313"",""StatusReg"":""Process completed successfully"",""ResDate"":""2026-03-21 01:28:29""},{""LDCMID"":""BYC00409"",""StatusReg"":""Process completed successfully"",""ResDate"":""2026-03-21 01:28:29""},{""LDCMID"":""BYC02171"",""StatusReg"":""Process completed successfully"",""ResDate"":""2026-03-21 01:28:29""},{""LDCMID"":""BYC02394"",""StatusReg"":""Process completed successfully"",""ResDate"":""2026-03-21 01:28:29""},{""LDCMID"":""BYC01922"",""StatusReg"":""Process completed successfully"",""ResDate"":""2026-03-21 01:28:29""},{""LDCMID"":""BYC00102"",""StatusReg"":""Process completed successfully"",""ResDate"":""2026-03-21 01:28:29""},{""LDCMID"":""BYC01169"",""StatusReg"":""Process completed successfully"",""ResDate"":""2026-03-21 01:28:29""},{""LDCMID"":""BYC00264"",""StatusReg"":""Process completed successfully"",""ResDate"":""2026-03-21 01:28:29""},{""LDCMID"":""BYC02578"",""StatusReg"":""Process completed successfully"",""ResDate"":""2026-03-21 01:28:29""},{""LDCMID"":""BYC02950"",""StatusReg"":""Process completed successfully"",""ResDate"":""2026-03-21 01:28:30""},{""LDCMID"":""BYC00002"",""StatusReg"":""Process completed successfully"",""ResDate"":""2026-03-21 01:28:30""},{""LDCMID"":""BYC02460"",""StatusReg"":""Process completed successfully"",""ResDate"":""2026-03-21 01:28:30""},{""LDCMID"":""BYC02919"",""StatusReg"":""Process completed successfully"",""ResDate"":""2026-03-21 01:28:30""},{""LDCMID"":""BYC02487"",""StatusReg"":""Process completed successfully"",""ResDate"":""2026-03-21 01:28:30""},{""LDCMID"":""BYC02721"",""StatusReg"":""Process completed successfully"",""ResDate"":""2026-03-21 01:28:30""},{""LDCMID"":""BYC00467"",""StatusReg"":""Process completed successfully"",""ResDate"":""2026-03-21 01:28:30""},{""LDCMID"":""BYC02561"",""StatusReg"":""Process completed successfully"",""ResDate"":""2026-03-21 01:28:30""},{""LDCMID"":""BYC02892"",""StatusReg"":""Process completed successfully"",""ResDate"":""2026-03-21 01:28:30""},{""LDCMID"":""B0203345"",""StatusReg"":""Process completed successfully"",""ResDate"":""2026-03-21 01:28:30""},{""LDCMID"":""B0201140"",""StatusReg"":""Process completed successfully"",""ResDate"":""2026-03-21 01:28:30""},{""LDCMID"":""B0201789"",""StatusReg"":""Process completed successfully"",""ResDate"":""2026-03-21 01:28:30""},{""LDCMID"":""B0201257"",""StatusReg"":""Process completed successfully"",""ResDate"":""2026-03-21 01:28:30""},{""LDCMID"":""B0201882"",""StatusReg"":""Process completed successfully"",""ResDate"":""2026-03-21 01:28:30""},{""LDCMID"":""B0203267"",""StatusReg"":""Process completed successfully"",""ResDate"":""2026-03-21 01:28:30""},{""LDCMID"":""B0201685"",""StatusReg"":""Process completed successfully"",""ResDate"":""2026-03-21 01:28:30""},{""LDCMID"":""B0202117"",""StatusReg"":""Process completed successfully"",""ResDate"":""2026-03-21 01:28:30""},{""LDCMID"":""B0201669"",""StatusReg"":""Process completed successfully"",""ResDate"":""2026-03-21 01:28:30""},{""LDCMID"":""B0201623"",""StatusReg"":""Process completed successfully"",""ResDate"":""2026-03-21 01:28:30""},{""LDCMID"":""B0202905"",""StatusReg"":""Process completed successfully"",""ResDate"":""2026-03-21 01:28:30""},{""LDCMID"":""B0202624"",""StatusReg"":""Process completed successfully"",""ResDate"":""2026-03-21 01:28:30""},{""LDCMID"":""B0202995"",""StatusReg"":""Process completed successfully"",""ResDate"":""2026-03-21 01:28:30""},{""LDCMID"":""B0200626"",""StatusReg"":""Process completed successfully"",""ResDate"":""2026-03-21 01:28:30""},{""LDCMID"":""B0203304"",""StatusReg"":""Process completed successfully"",""ResDate"":""2026-03-21 01:28:30""},{""LDCMID"":""B0200915"",""StatusReg"":""Process completed successfully"",""ResDate"":""2026-03-21 01:28:30""},{""LDCMID"":""B0203349"",""StatusReg"":""Process completed successfully"",""ResDate"":""2026-03-21 01:28:30""},{""LDCMID"":""B0203262"",""StatusReg"":""Process completed successfully"",""ResDate"":""2026-03-21 01:28:30""},{""LDCMID"":""B0203061"",""StatusReg"":""Process completed successfully"",""ResDate"":""2026-03-21 01:28:30""},{""LDCMID"":""B0200724"",""StatusReg"":""Process completed successfully"",""ResDate"":""2026-03-21 01:28:30""},{""LDCMID"":""B0201210"",""StatusReg"":""Process completed successfully"",""ResDate"":""2026-03-21 01:28:30""},{""LDCMID"":""B0201867"",""StatusReg"":""Process completed successfully"",""ResDate"":""2026-03-21 01:28:30""},{""LDCMID"":""B0202119"",""StatusReg"":""Process completed successfully"",""ResDate"":""2026-03-21 01:28:30""},{""LDCMID"":""B0202884"",""StatusReg"":""Process completed successfully"",""ResDate"":""2026-03-21 01:28:30""},{""LDCMID"":""B0201839"",""StatusReg"":""Process completed successfully"",""ResDate"":""2026-03-21 01:28:30""},{""LDCMID"":""B0202090"",""StatusReg"":""Process completed successfully"",""ResDate"":""2026-03-21 01:28:30""},{""LDCMID"":""B0201840"",""StatusReg"":""Process completed successfully"",""ResDate"":""2026-03-21 01:28:30""},{""LDCMID"":""B0203287"",""StatusReg"":""Process completed successfully"",""ResDate"":""2026-03-21 01:28:30""},{""LDCMID"":""B0201160"",""StatusReg"":""Process completed successfully"",""ResDate"":""2026-03-21 01:28:30""},{""LDCMID"":""B0202825"",""StatusReg"":""Process completed successfully"",""ResDate"":""2026-03-21 01:28:30""},{""LDCMID"":""B0202842"",""StatusReg"":""Process completed successfully"",""ResDate"":""2026-03-21 01:28:30""},{""LDCMID"":""B0202097"",""StatusReg"":""Process completed successfully"",""ResDate"":""2026-03-21 01:28:30""},{""LDCMID"":""B0202636"",""StatusReg"":""Process completed successfully"",""ResDate"":""2026-03-21 01:28:30""},{""LDCMID"":""B0201341"",""StatusReg"":""Process completed successfully"",""ResDate"":""2026-03-21 01:28:30""},{""LDCMID"":""B0202139"",""StatusReg"":""Process completed successfully"",""ResDate"":""2026-03-21 01:28:30""},{""LDCMID"":""B0202982"",""StatusReg"":""Process completed successfully"",""ResDate"":""2026-03-21 01:28:30""},{""LDCMID"":""B0201956"",""StatusReg"":""Process completed successfully"",""ResDate"":""2026-03-21 01:28:30""},{""LDCMID"":""B0202869"",""StatusReg"":""Process completed successfully"",""ResDate"":""2026-03-21 01:28:30""},{""LDCMID"":""B0203177"",""StatusReg"":""Process completed successfully"",""ResDate"":""2026-03-21 01:28:30""},{""LDCMID"":""B0200383"",""StatusReg"":""Process completed successfully"",""ResDate"":""2026-03-21 01:28:30""},{""LDCMID"":""B0202895"",""StatusReg"":""Process completed successfully"",""ResDate"":""2026-03-21 01:28:30""},{""LDCMID"":""B0202717"",""StatusReg"":""Process completed successfully"",""ResDate"":""2026-03-21 01:28:30""},{""LDCMID"":""B0202389"",""StatusReg"":""Process completed successfully"",""ResDate"":""2026-03-21 01:28:30""},{""LDCMID"":""B0203101"",""StatusReg"":""Process completed successfully"",""ResDate"":""2026-03-21 01:28:30""},{""LDCMID"":""B0202089"",""StatusReg"":""Process completed successfully"",""ResDate"":""2026-03-21 01:28:30""},{""LDCMID"":""B0201419"",""StatusReg"":""Process completed successfully"",""ResDate"":""2026-03-21 01:28:30""},{""LDCMID"":""B0202506"",""StatusReg"":""Process completed successfully"",""ResDate"":""2026-03-21 01:28:30""},{""LDCMID"":""B0202975"",""StatusReg"":""Process completed successfully"",""ResDate"":""2026-03-21 01:28:30""},{""LDCMID"":""B0203310"",""StatusReg"":""Process completed successfully"",""ResDate"":""2026-03-21 01:28:30""},{""LDCMID"":""B0201552"",""StatusReg"":""Process completed successfully"",""ResDate"":""2026-03-21 01:28:30""},{""LDCMID"":""B0200731"",""StatusReg"":""Process completed successfully"",""ResDate"":""2026-03-21 01:28:30""},{""LDCMID"":""B0201093"",""StatusReg"":""Process completed successfully"",""ResDate"":""2026-03-21 01:28:30""},{""LDCMID"":""B0201902"",""StatusReg"":""Process completed successfully"",""ResDate"":""2026-03-21 01:28:30""},{""LDCMID"":""B0203163"",""StatusReg"":""Process completed successfully"",""ResDate"":""2026-03-21 01:28:30""},{""LDCMID"":""B0201376"",""StatusReg"":""Process completed successfully"",""ResDate"":""2026-03-21 01:28:30""},{""LDCMID"":""B0202858"",""StatusReg"":""Process completed successfully"",""ResDate"":""2026-03-21 01:28:30""},{""LDCMID"":""B0201150"",""StatusReg"":""Process completed successfully"",""ResDate"":""2026-03-21 01:28:30""},{""LDCMID"":""B0200954"",""StatusReg"":""Process completed successfully"",""ResDate"":""2026-03-21 01:28:30""},{""LDCMID"":""B0202749"",""StatusReg"":""Process completed successfully"",""ResDate"":""2026-03-21 01:28:30""},{""LDCMID"":""B0202663"",""StatusReg"":""Process completed successfully"",""ResDate"":""2026-03-21 01:28:30""},{""LDCMID"":""B0201624"",""StatusReg"":""Process completed successfully"",""ResDate"":""2026-03-21 01:28:30""},{""LDCMID"":""B0201903"",""StatusReg"":""Process completed successfully"",""ResDate"":""2026-03-21 01:28:30""},{""LDCMID"":""B0201888"",""StatusReg"":""Process completed successfully"",""ResDate"":""2026-03-21 01:28:30""},{""LDCMID"":""B0201723"",""StatusReg"":""Process completed successfully"",""ResDate"":""2026-03-21 01:28:30""},{""LDCMID"":""B0203172"",""StatusReg"":""Process completed successfully"",""ResDate"":""2026-03-21 01:28:30""},{""LDCMID"":""B0200388"",""StatusReg"":""Process completed successfully"",""ResDate"":""2026-03-21 01:28:30""},{""LDCMID"":""B0200281"",""StatusReg"":""Process completed successfully"",""ResDate"":""2026-03-21 01:28:30""},{""LDCMID"":""B0200369"",""StatusReg"":""Process completed successfully"",""ResDate"":""2026-03-21 01:28:30""},{""LDCMID"":""B0201665"",""StatusReg"":""Process completed successfully"",""ResDate"":""2026-03-21 01:28:30""},{""LDCMID"":""B0202883"",""StatusReg"":""Process completed successfully"",""ResDate"":""2026-03-21 01:28:30""},{""LDCMID"":""B0201138"",""StatusReg"":""Process completed successfully"",""ResDate"":""2026-03-21 01:28:30""},{""LDCMID"":""B0203022"",""StatusReg"":""Process completed successfully"",""ResDate"":""2026-03-21 01:28:30""},{""LDCMID"":""B0201361"",""StatusReg"":""Process completed successfully"",""ResDate"":""2026-03-21 01:28:30""},{""LDCMID"":""B0203247"",""StatusReg"":""Process completed successfully"",""ResDate"":""2026-03-21 01:28:30""},{""LDCMID"":""B0203019"",""StatusReg"":""Process completed successfully"",""ResDate"":""2026-03-21 01:28:30""},{""LDCMID"":""B0200065"",""StatusReg"":""Process completed successfully"",""ResDate"":""2026-03-21 01:28:30""},{""LDCMID"":""B0202942"",""StatusReg"":""Process completed successfully"",""ResDate"":""2026-03-21 01:28:30""},{""LDCMID"":""B0202738"",""StatusReg"":""Process completed successfully"",""ResDate"":""2026-03-21 01:28:31""},{""LDCMID"":""B0101680"",""StatusReg"":""Process completed successfully"",""ResDate"":""2026-03-21 01:28:31""},{""LDCMID"":""B0203238"",""StatusReg"":""Process completed successfully"",""ResDate"":""2026-03-21 01:28:31""},{""LDCMID"":""B0202176"",""StatusReg"":""Process completed successfully"",""ResDate"":""2026-03-21 01:28:31""},{""LDCMID"":""B0202903"",""StatusReg"":""Process completed successfully"",""ResDate"":""2026-03-21 01:28:31""},{""LDCMID"":""B0202099"",""StatusReg"":""Process completed successfully"",""ResDate"":""2026-03-21 01:28:31""},{""LDCMID"":""B0201554"",""StatusReg"":""Process completed successfully"",""ResDate"":""2026-03-21 01:28:31""},{""LDCMID"":""B0200396"",""StatusReg"":""Process completed successfully"",""ResDate"":""2026-03-21 01:28:31""},{""LDCMID"":""B0201493"",""StatusReg"":""Process completed successfully"",""ResDate"":""2026-03-21 01:28:31""},{""LDCMID"":""B0202912"",""StatusReg"":""Process completed successfully"",""ResDate"":""2026-03-21 01:28:31""},{""LDCMID"":""B0203040"",""StatusReg"":""Process completed successfully"",""ResDate"":""2026-03-21 01:28:31""},{""LDCMID"":""B0201223"",""StatusReg"":""Process completed successfully"",""ResDate"":""2026-03-21 01:28:31""},{""LDCMID"":""B0202850"",""StatusReg"":""Process completed successfully"",""ResDate"":""2026-03-21 01:28:31""},{""LDCMID"":""B0202988"",""StatusReg"":""Process completed successfully"",""ResDate"":""2026-03-21 01:28:31""},{""LDCMID"":""B0201250"",""StatusReg"":""Process completed successfully"",""ResDate"":""2026-03-21 01:28:31""},{""LDCMID"":""B0202951"",""StatusReg"":""Process completed successfully"",""ResDate"":""2026-03-21 01:28:31""},{""LDCMID"":""B0202513"",""StatusReg"":""Process completed successfully"",""ResDate"":""2026-03-21 01:28:31""},{""LDCMID"":""B0203296"",""StatusReg"":""Process completed successfully"",""ResDate"":""2026-03-21 01:28:31""},{""LDCMID"":""B0201149"",""StatusReg"":""Process completed successfully"",""ResDate"":""2026-03-21 01:28:31""},{""LDCMID"":""B0202220"",""StatusReg"":""Process completed successfully"",""ResDate"":""2026-03-21 01:28:31""},{""LDCMID"":""B0202836"",""StatusReg"":""Process completed successfully"",""ResDate"":""2026-03-21 01:28:31""},{""LDCMID"":""B0202664"",""StatusReg"":""Process completed successfully"",""ResDate"":""2026-03-21 01:28:31""},{""LDCMID"":""B0202250"",""StatusReg"":""Process completed successfully"",""ResDate"":""2026-03-21 01:28:31""},{""LDCMID"":""B0202213"",""StatusReg"":""Process completed successfully"",""ResDate"":""2026-03-21 01:28:31""},{""LDCMID"":""B0201537"",""StatusReg"":""Process completed successfully"",""ResDate"":""2026-03-21 01:28:31""},{""LDCMID"":""B0203213"",""StatusReg"":""Process completed successfully"",""ResDate"":""2026-03-21 01:28:31""},{""LDCMID"":""B0201684"",""StatusReg"":""Process completed successfully"",""ResDate"":""2026-03-21 01:28:31""},{""LDCMID"":""B0201500"",""StatusReg"":""Process completed successfully"",""ResDate"":""2026-03-21 01:28:31""},{""LDCMID"":""B0203590"",""StatusReg"":""Process completed successfully"",""ResDate"":""2026-03-21 01:28:31""},{""LDCMID"":""B0203206"",""StatusReg"":""Process completed successfully"",""ResDate"":""2026-03-21 01:28:31""},{""LDCMID"":""B0202892"",""StatusReg"":""Process completed successfully"",""ResDate"":""2026-03-21 01:28:31""},{""LDCMID"":""B0203176"",""StatusReg"":""Process completed successfully"",""ResDate"":""2026-03-21 01:28:31""},{""LDCMID"":""B0202823"",""StatusReg"":""Process completed successfully"",""ResDate"":""2026-03-21 01:28:31""},{""LDCMID"":""B0200538"",""StatusReg"":""Process completed successfully"",""ResDate"":""2026-03-21 01:28:31""},{""LDCMID"":""B0202517"",""StatusReg"":""Process completed successfully"",""ResDate"":""2026-03-21 01:28:31""},{""LDCMID"":""B0201229"",""StatusReg"":""Process completed successfully"",""ResDate"":""2026-03-21 01:28:31""},{""LDCMID"":""B0203284"",""StatusReg"":""Process completed successfully"",""ResDate"":""2026-03-21 01:28:31""},{""LDCMID"":""B0200600"",""StatusReg"":""Process completed successfully"",""ResDate"":""2026-03-21 01:28:31""},{""LDCMID"":""B0203169"",""StatusReg"":""Process completed successfully"",""ResDate"":""2026-03-21 01:28:31""},{""LDCMID"":""B0201490"",""StatusReg"":""Process completed successfully"",""ResDate"":""2026-03-21 01:28:31""},{""LDCMID"":""B0201122"",""StatusReg"":""Process completed successfully"",""ResDate"":""2026-03-21 01:28:31""},{""LDCMID"":""B0203338"",""StatusReg"":""Process completed successfully"",""ResDate"":""2026-03-21 01:28:31""},{""LDCMID"":""B0203382"",""StatusReg"":""Process completed successfully"",""ResDate"":""2026-03-21 01:28:31""},{""LDCMID"":""B0202747"",""StatusReg"":""Process completed successfully"",""ResDate"":""2026-03-21 01:28:31""},{""LDCMID"":""B0202750"",""StatusReg"":""Process completed successfully"",""ResDate"":""2026-03-21 01:28:31""},{""LDCMID"":""B0202466"",""StatusReg"":""Process completed successfully"",""ResDate"":""2026-03-21 01:28:31""},{""LDCMID"":""B0201215"",""StatusReg"":""Process completed successfully"",""ResDate"":""2026-03-21 01:28:31""},{""LDCMID"":""B0202182"",""StatusReg"":""Process completed successfully"",""ResDate"":""2026-03-21 01:28:31""},{""LDCMID"":""B0202333"",""StatusReg"":""Process completed successfully"",""ResDate"":""2026-03-21 01:28:31""},{""LDCMID"":""B0203302"",""StatusReg"":""Process completed successfully"",""ResDate"":""2026-03-21 01:28:31""},{""LDCMID"":""B0202223"",""StatusReg"":""Process completed successfully"",""ResDate"":""2026-03-21 01:28:31""},{""LDCMID"":""B0203168"",""StatusReg"":""Process completed successfully"",""ResDate"":""2026-03-21 01:28:31""},{""LDCMID"":""B0203531"",""StatusReg"":""Process completed successfully"",""ResDate"":""2026-03-21 01:28:31""},{""LDCMID"":""B0202687"",""StatusReg"":""Process completed successfully"",""ResDate"":""2026-03-21 01:28:31""},{""LDCMID"":""B0202064"",""StatusReg"":""Process completed successfully"",""ResDate"":""2026-03-21 01:28:31""},{""LDCMID"":""B0200033"",""StatusReg"":""Process completed successfully"",""ResDate"":""2026-03-21 01:28:31""},{""LDCMID"":""B0202673"",""StatusReg"":""Process completed successfully"",""ResDate"":""2026-03-21 01:28:31""},{""LDCMID"":""B0202657"",""StatusReg"":""Process completed successfully"",""ResDate"":""2026-03-21 01:28:31""},{""LDCMID"":""B0202848"",""StatusReg"":""Process completed successfully"",""ResDate"":""2026-03-21 01:28:31""},{""LDCMID"":""B0200502"",""StatusReg"":""Process completed successfully"",""ResDate"":""2026-03-21 01:28:31""},{""LDCMID"":""B0201141"",""StatusReg"":""Process completed successfully"",""ResDate"":""2026-03-21 01:28:31""},{""LDCMID"":""B0201205"",""StatusReg"":""Process completed successfully"",""ResDate"":""2026-03-21 01:28:31""},{""LDCMID"":""B0200398"",""StatusReg"":""Process completed successfully"",""ResDate"":""2026-03-21 01:28:31""},{""LDCMID"":""B0202002"",""StatusReg"":""Process completed successfully"",""ResDate"":""2026-03-21 01:28:31""},{""LDCMID"":""B0203196"",""StatusReg"":""Process completed successfully"",""ResDate"":""2026-03-21 01:28:31""},{""LDCMID"":""B0201164"",""StatusReg"":""Process completed successfully"",""ResDate"":""2026-03-21 01:28:31""},{""LDCMID"":""B0203339"",""StatusReg"":""Process completed successfully"",""ResDate"":""2026-03-21 01:28:31""}]}}
A7: 4 | D7: ate=20260321083211, TypeStatus=OK, NGDate=null, NGRECBY=null, ReplaceSN=null}, {LDCMID=B0202657, IMEI=860466063287306, ICCID=8966044925100039445, IMSI=520043600676179, ProStatus=PROD, ProDate=20260320190848, SendDate=20260321083211, TypeStatus=OK, NGDate=null, NGRECBY=null, ReplaceSN=null}, {LDCMID=B0202848, IMEI=860466063287231, ICCID=8966044925100037530, IMSI=520043600675988, ProStatus=PROD, ProDate=20260320190902, SendDate=20260321083211, TypeStatus=OK, NGDate=null, NGRECBY=null, ReplaceSN=null}, {LDCMID=B0200502, IMEI=860466063268710, ICCID=8966044925100072669, IMSI=520043600679501, ProStatus=PROD, ProDate=20260320190918, SendDate=20260321083211, TypeStatus=OK, NGDate=null, NGRECBY=null, ReplaceSN=null}, {LDCMID=B0201141, IMEI=860466063287413, ICCID=8966044925100054584, IMSI=520043600677693, ProStatus=PROD, ProDate=20260320190930, SendDate=20260321083211, TypeStatus=OK, NGDate=null, NGRECBY=null, ReplaceSN=null}, {LDCMID=B0201205, IMEI=860466063287280, ICCID=8966044925100053941, IMSI=520043600677629, ProStatus=PROD, ProDate=20260320190944, SendDate=20260321083211, TypeStatus=OK, NGDate=null, NGRECBY=null, ReplaceSN=null}, {LDCMID=B0200398, IMEI=860466063268413, ICCID=8966044925100073709, IMSI=520043600679605, ProStatus=PROD, ProDate=20260320190958, SendDate=20260321083211, TypeStatus=OK, NGDate=null, NGRECBY=null, ReplaceSN=null}, {LDCMID=B0202002, IMEI=860466063288932, ICCID=8966044925100044254, IMSI=520043600676660, ProStatus=PROD, ProDate=20260320191155, SendDate=20260321083211, TypeStatus=OK, NGDate=null, NGRECBY=null, ReplaceSN=null}, {LDCMID=B0203196, IMEI=860466063288965, ICCID=8966044925100034073, IMSI=520043600675642, ProStatus=PROD, ProDate=20260320191207, SendDate=20260321083211, TypeStatus=OK, NGDate=null, NGRECBY=null, ReplaceSN=null}, {LDCMID=B0201164, IMEI=860466063270435, ICCID=8966044925100054378, IMSI=520043600677672, ProStatus=PROD, ProDate=20260320191219, SendDate=20260321083211, TypeStatus=OK, NGDate=null, NGRECBY=null, ReplaceSN=null}, {LDCMID=B0203339, IMEI=860466063288890, ICCID=8966044925100032622, IMSI=520043600675497, ProStatus=PROD, ProDate=20260320191231, SendDate=20260321083211, TypeStatus=OK, NGDate=null, NGRECBY=null, ReplaceSN=null}]}}
A8: 5
A9: 6
A10: 7
A11: 8
A12: 9
A13: 10
A14: 11
A15: 12
A16: 13
A17: 14
A18: 15
A19: 16
... A55: 52

Sheet DTEN TCAP Linkage
A1: No. | B1: date | C1: Request ID | D1: Request for TCAP Cloud | E1: Response from TCAP Cloud
